use std::error::Error;
use std::fmt;

// Mock error types for testing
#[derive(Debug)]
struct MockNetworkError(String);

#[derive(Debug)]
struct MockDiskError(String);

#[derive(Debug)]
struct MockIsoError(String);

impl fmt::Display for MockNetworkError {
    fn fmt(&self, f: &mut fmt::Formatter<'_>) -> fmt::Result {
        write!(f, "Network error: {}", self.0)
    }
}

impl fmt::Display for MockDiskError {
    fn fmt(&self, f: &mut fmt::Formatter<'_>) -> fmt::Result {
        write!(f, "Disk error: {}", self.0)
    }
}

impl fmt::Display for MockIsoError {
    fn fmt(&self, f: &mut fmt::Formatter<'_>) -> fmt::Result {
        write!(f, "ISO error: {}", self.0)
    }
}

impl Error for MockNetworkError {}
impl Error for MockDiskError {}
impl Error for MockIsoError {}

#[test]
fn test_error_display() {
    let net_err = MockNetworkError("Connection failed".to_string());
    assert_eq!(format!("{}", net_err), "Network error: Connection failed");
    
    let disk_err = MockDiskError("Partition not found".to_string());
    assert_eq!(format!("{}", disk_err), "Disk error: Partition not found");
    
    let iso_err = MockIsoError("Mount failed".to_string());
    assert_eq!(format!("{}", iso_err), "ISO error: Mount failed");
}

#[test]
fn test_error_debug() {
    let err = MockNetworkError("Test error".to_string());
    let debug_str = format!("{:?}", err);
    assert!(debug_str.contains("MockNetworkError"));
    assert!(debug_str.contains("Test error"));
}

#[test]
fn test_error_chaining() {
    use std::io;
    
    #[derive(Debug)]
    struct ChainedError {
        message: String,
        source: Option<Box<dyn Error + Send + Sync>>,
    }
    
    impl fmt::Display for ChainedError {
        fn fmt(&self, f: &mut fmt::Formatter<'_>) -> fmt::Result {
            write!(f, "{}", self.message)
        }
    }
    
    impl Error for ChainedError {
        fn source(&self) -> Option<&(dyn Error + 'static)> {
            self.source.as_ref().map(|e| e.as_ref() as &(dyn Error + 'static))
        }
    }
    
    let io_error = io::Error::new(io::ErrorKind::NotFound, "File not found");
    let chained = ChainedError {
        message: "Failed to load config".to_string(),
        source: Some(Box::new(io_error)),
    };
    
    assert_eq!(format!("{}", chained), "Failed to load config");
    assert!(chained.source().is_some());
}

#[test]
fn test_error_conversion() {
    #[derive(Debug)]
    enum AppError {
        Network(MockNetworkError),
        Disk(MockDiskError),
        Iso(MockIsoError),
    }
    
    impl fmt::Display for AppError {
        fn fmt(&self, f: &mut fmt::Formatter<'_>) -> fmt::Result {
            match self {
                AppError::Network(e) => write!(f, "App network error: {}", e),
                AppError::Disk(e) => write!(f, "App disk error: {}", e),
                AppError::Iso(e) => write!(f, "App ISO error: {}", e),
            }
        }
    }
    
    impl Error for AppError {}
    
    impl From<MockNetworkError> for AppError {
        fn from(err: MockNetworkError) -> Self {
            AppError::Network(err)
        }
    }
    
    let net_err = MockNetworkError("Test".to_string());
    let app_err: AppError = net_err.into();
    
    assert!(matches!(app_err, AppError::Network(_)));
}

#[test]
fn test_error_context() {
    #[derive(Debug)]
    struct ContextError {
        context: String,
        error: Box<dyn Error + Send + Sync>,
    }
    
    impl fmt::Display for ContextError {
        fn fmt(&self, f: &mut fmt::Formatter<'_>) -> fmt::Result {
            write!(f, "{}: {}", self.context, self.error)
        }
    }
    
    impl Error for ContextError {}
    
    let base_err = MockDiskError("Write failed".to_string());
    let ctx_err = ContextError {
        context: "While formatting partition".to_string(),
        error: Box::new(base_err),
    };
    
    assert_eq!(
        format!("{}", ctx_err),
        "While formatting partition: Disk error: Write failed"
    );
}

#[test]
fn test_error_types() {
    // Test various error scenarios
    let errors: Vec<Box<dyn Error>> = vec![
        Box::new(MockNetworkError("DHCP timeout".to_string())),
        Box::new(MockDiskError("Invalid partition table".to_string())),
        Box::new(MockIsoError("Corrupted ISO file".to_string())),
    ];
    
    for err in errors {
        assert!(!err.to_string().is_empty());
    }
}

#[test]
fn test_error_recovery() {
    fn operation_that_might_fail(should_fail: bool) -> Result<String, MockNetworkError> {
        if should_fail {
            Err(MockNetworkError("Operation failed".to_string()))
        } else {
            Ok("Success".to_string())
        }
    }
    
    // Test failure case
    let result = operation_that_might_fail(true);
    assert!(result.is_err());
    assert_eq!(
        result.unwrap_err().to_string(),
        "Network error: Operation failed"
    );
    
    // Test success case
    let result = operation_that_might_fail(false);
    assert!(result.is_ok());
    assert_eq!(result.unwrap(), "Success");
}

#[test]
fn test_error_aggregation() {
    struct MultiError {
        errors: Vec<Box<dyn Error + Send + Sync>>,
    }
    
    impl fmt::Display for MultiError {
        fn fmt(&self, f: &mut fmt::Formatter<'_>) -> fmt::Result {
            write!(f, "Multiple errors occurred: ")?;
            for (i, err) in self.errors.iter().enumerate() {
                if i > 0 {
                    write!(f, ", ")?;
                }
                write!(f, "{}", err)?;
            }
            Ok(())
        }
    }
    
    impl fmt::Debug for MultiError {
        fn fmt(&self, f: &mut fmt::Formatter<'_>) -> fmt::Result {
            f.debug_struct("MultiError")
                .field("count", &self.errors.len())
                .finish()
        }
    }
    
    impl Error for MultiError {}
    
    let multi = MultiError {
        errors: vec![
            Box::new(MockNetworkError("Error 1".to_string())),
            Box::new(MockDiskError("Error 2".to_string())),
        ],
    };
    
    let display = format!("{}", multi);
    assert!(display.contains("Error 1"));
    assert!(display.contains("Error 2"));
}